Workbook

Sheet Start Here
B1: KAIZEN XP | BREAKDOWN ANALYSIS DASHBOARD
B2: Log every breakdown. See which machine to fix first, and prove it got better.
B5: WHAT IT DOES | C5: Turns a simple breakdown log into MTBF, MTTR, availability, downtime cost and a Pareto of your worst machines and failure types. Updates itself every time you add a line.
B6: WHY IT MATTERS | C6: Every site has a breakdown log. Almost nobody turns it into a decision. This does it for you: the dashboard tells you which machine and which failure type to attack first.
B8: HOW TO USE IT | C8: 1. Look at the Dashboard first. It is running on SAMPLE DATA so you can see it working.
C9: 2. When you are ready, go to Breakdown Log, select the sample rows and press Delete.
C10: 3. On Setup, type your line name, the period you want to look at, your run hours and your machine list.
C11: 4. Log every breakdown: date, shift, machine, failure type, minutes down. Pick from the lists.
C12: 5. Check the Dashboard weekly. Attack the top bar on the Pareto with 5 Whys or an RCFA.
B14: THE NUMBERS | C14: MTBF (Mean Time Between Failures): run hours divided by breakdowns. Higher is better.
C15: MTTR (Mean Time To Repair): downtime minutes divided by breakdowns. Lower is better.
C16: Availability: the share of planned run time the line was not broken down.
C17: Pareto: machines and failure types in order of downtime, with a running total. The first one or two bars are usually most of the problem.
B19: BREAKDOWN OR ASSIST? | C19: A breakdown needs a technician or engineer and stops the job. The quick stops an operator clears in a minute are assists: log those in the Kaizen XP MTBA Assist Tracker.
B21: WORKS IN | C21: Microsoft Excel, Google Sheets (File > Import) and Apple Numbers. The Dashboard and Workings are locked so formulas cannot be broken by accident.
B23: LEGEND | C23: Type here
C24: Worked out for you (locked)
B26: "Do what nobody else can be bothered to do, and you'll get what nobody else gets."
B27: © 2026 Kaizen XP. Licensed for one person's use. Please do not share or resell.

Sheet Dashboard
B1: KAIZEN XP | BREAKDOWN ANALYSIS DASHBOARD
B2: ="Line: "&Setup!C6&" Period: "&TEXT(Setup!C7,"d mmm yyyy")&" to "&TEXT(Setup!C8,"d mmm yyyy") -> Line: Line 3 (sample) Period: 1 Apr 2026 to 30 Sep 2026
B5: BREAKDOWNS | D5: HOURS DOWN | F5: MTBF (HOURS) | H5: MTTR (MINS) | J5: AVAILABILITY | L5: DOWNTIME COST | N5: ROOT CAUSE FOUND
B6: =Workings!C56 -> 132 | D6: =Workings!C57/60 -> 74.316667 | F6: =Workings!C59 -> 20.232449 | H6: =Workings!C60 -> 33.780303 | J6: =Workings!C61 -> 0.97292653 | L6: =Workings!C62 -> 18579.167 | N6: =Workings!C63 -> 0.34848485
B10: =IF(Workings!C56=0,"Log your first breakdown and the machine to fix first shows here.","FIX FIRST: "&Workings!H7&". It caused "&TEXT(Workings!C64,"0%")&" of all downtime ("&TEXT(Workings!J7,"0.0")&" hours) in this period. Biggest failure type overall: "&Workings!H26&" ("&TEXT(Workings!C65,"0%")&").") -> FIX FIRST: Labeller. It caused 33% of all downtime (24.8 hours) in this period. Biggest failure type overall: Mechanical (31%).
B45: WORST MACHINES (attack the top one first with 5 Whys or the Kaizen XP RCFA Template)
B46: MACHINE | E46: BREAKDOWNS | G46: HOURS DOWN | I46: MTTR (MINS) | K46: SHARE | M46: COST
B47: =Workings!H7 -> Labeller | E47: =Workings!L7 -> 31 | G47: =Workings!J7 -> 24.783333 | I47: =IF(Workings!L7=0,"-",Workings!I7/Workings!L7) -> 47.967742 | K47: =IF(Workings!C57=0,0,Workings!I7/Workings!C57) -> 0.33348284 | M47: =Workings!I7/60*N(Setup!$C$11) -> 6195.8333
B48: =Workings!H8 -> Filler | E48: =Workings!L8 -> 21 | G48: =Workings!J8 -> 8.9666667 | I48: =IF(Workings!L8=0,"-",Workings!I8/Workings!L8) -> 25.619048 | K48: =IF(Workings!C57=0,0,Workings!I8/Workings!C57) -> 0.12065486 | M48: =Workings!I8/60*N(Setup!$C$11) -> 2241.6667
B49: =Workings!H9 -> Case packer | E49: =Workings!L9 -> 18 | G49: =Workings!J9 -> 8.6333333 | I49: =IF(Workings!L9=0,"-",Workings!I9/Workings!L9) -> 28.777778 | K49: =IF(Workings!C57=0,0,Workings!I9/Workings!C57) -> 0.11616954 | M49: =Workings!I9/60*N(Setup!$C$11) -> 2158.3333
B50: =Workings!H10 -> Palletiser | E50: =Workings!L10 -> 14 | G50: =Workings!J10 -> 8.4166667 | I50: =IF(Workings!L10=0,"-",Workings!I10/Workings!L10) -> 36.071429 | K50: =IF(Workings!C57=0,0,Workings!I10/Workings!C57) -> 0.11325409 | M50: =Workings!I10/60*N(Setup!$C$11) -> 2104.1667
B51: =Workings!H11 -> Shrink wrapper | E51: =Workings!L11 -> 15 | G51: =Workings!J11 -> 7.85 | I51: =IF(Workings!L11=0,"-",Workings!I11/Workings!L11) -> 31.4 | K51: =IF(Workings!C57=0,0,Workings!I11/Workings!C57) -> 0.10562906 | M51: =Workings!I11/60*N(Setup!$C$11) -> 1962.5
B53: © 2026 Kaizen XP. Licensed for one person's use. Please do not share or resell.

Sheet Breakdown Log
B1: BREAKDOWN LOG
B2: One line per breakdown. Pick machine, failure type and shift from the lists. Minutes down = from stopped to running again.
B4: The rows below are SAMPLE DATA so you can see the dashboard working. When you are ready: select them, press Delete, then set your own machines and dates on the Setup tab.
B6: DATE | C6: SHIFT | D6: MACHINE | E6: FAILURE TYPE | F6: WHAT HAPPENED | G6: MINUTES DOWN | H6: FIXED BY | I6: ROOT CAUSE FOUND? | J6: RCFA REF
B7: 46113 | C7: Lates | D7: Conveyors | E7: Electrical | F7: Motor tripped on overload | G7: 9 | H7: Day tech | I7: In progress
B8: 46114 | C8: Lates | D8: Filler | E8: Mechanical | F8: Bearing noise, replaced | G8: 28 | H8: Operator and tech | I8: No
B9: 46115 | C9: Nights | D9: Filler | E9: Other | F9: Guard interlock fault | G9: 21 | H9: Day tech | I9: Yes | J9: RCFA-001
B10: 46115 | C10: Days | D10: Case packer | E10: Sensor or controls | F10: PLC fault, reset and checked | G10: 20 | H10: Night tech | I10: Yes
B11: 46118 | C11: Nights | D11: Capper | E11: Pneumatic | F11: Air leak on cylinder | G11: 17 | H11: Night tech | I11: No
B12: 46119 | C12: Nights | D12: Labeller | E12: Material or supply | F12: Film roll faulty | G12: 52 | H12: Day tech | I12: No
B13: 46121 | C13: Days | D13: Filler | E13: Changeover or setup | F13: Overran changeover | G13: 13 | H13: Operator and tech | I13: Yes | J13: RCFA-002
B14: 46121 | C14: Earlies | D14: Shrink wrapper | E14: Changeover or setup | F14: Wrong change parts fitted | G14: 21 | H14: Day tech | I14: No
B15: 46122 | C15: Nights | D15: Filler | E15: Sensor or controls | F15: Photo eye misaligned | G15: 43 | H15: Shift engineer | I15: Yes
B16: 46125 | C16: Lates | D16: Labeller | E16: Sensor or controls | F16: Proximity sensor failed | G16: 41 | H16: Shift engineer | I16: Yes
B17: 46126 | C17: Earlies | D17: Labeller | E17: Mechanical | F17: Guide rail worked loose | G17: 36 | H17: Shift engineer | I17: Yes | J17: RCFA-003
B18: 46127 | C18: Lates | D18: Capper | E18: Electrical | F18: Motor tripped on overload | G18: 20 | H18: Shift engineer | I18: Yes | J18: RCFA-004
B19: 46128 | C19: Nights | D19: Labeller | E19: Material or supply | F19: Label reel splice failed | G19: 17 | H19: Operator and tech | I19: Yes
B20: 46128 | C20: Earlies | D20: Conveyors | E20: Sensor or controls | F20: Proximity sensor failed | G20: 42 | H20: Shift engineer | I20: In progress
B21: 46129 | C21: Days | D21: Labeller | E21: Material or supply | F21: Label reel splice failed | G21: 28 | H21: Day tech | I21: Yes | J21: RCFA-005
B22: 46132 | C22: Nights | D22: Labeller | E22: Sensor or controls | F22: Proximity sensor failed | G22: 24 | H22: Operator and tech | I22: Yes | J22: RCFA-006
B23: 46132 | C23: Days | D23: Filler | E23: Mechanical | F23: Guide rail worked loose | G23: 25 | H23: Electrician | I23: Yes | J23: RCFA-007
B24: 46133 | C24: Days | D24: Palletiser | E24: Mechanical | F24: Guide rail worked loose | G24: 28 | H24: Day tech | I24: No
B25: 46134 | C25: Nights | D25: Case packer | E25: Material or supply | F25: Film roll faulty | G25: 22 | H25: Night tech | I25: No
B26: 46135 | C26: Earlies | D26: Shrink wrapper | E26: Other | F26: Lubrication missed, seized | G26: 95 | H26: Day tech | I26: Yes
B27: 46135 | C27: Nights | D27: Depalletiser | E27: Changeover or setup | F27: Settings not reset after changeover | G27: 26 | H27: Electrician | I27: No
B28: 46136 | C28: Days | D28: Labeller | E28: Sensor or controls | F28: Proximity sensor failed | G28: 30 | H28: Electrician | I28: Yes
B29: 46141 | C29: Nights | D29: Shrink wrapper | E29: Changeover or setup | F29: Wrong change parts fitted | G29: 26 | H29: Shift engineer | I29: In progress
B30: 46142 | C30: Lates | D30: Filler | E30: Other | F30: Lubrication missed, seized | G30: 35 | H30: Night tech | I30: Yes | J30: RCFA-008
B31: 46143 | C31: Lates | D31: Palletiser | E31: Other | F31: Guard interlock fault | G31: 34 | H31: Day tech | I31: No
B32: 46143 | C32: Earlies | D32: Shrink wrapper | E32: Changeover or setup | F32: Wrong change parts fitted | G32: 27 | H32: Day tech | I32: Yes
B33: 46146 | C33: Lates | D33: Conveyors | E33: Sensor or controls | F33: PLC fault, reset and checked | G33: 53 | H33: Night tech | I33: In progress
B34: 46147 | C34: Lates | D34: Case packer | E34: Material or supply | F34: Label reel splice failed | G34: 56 | H34: Night tech | I34: In progress
B35: 46147 | C35: Earlies | D35: Filler | E35: Changeover or setup | F35: Wrong change parts fitted | G35: 29 | H35: Operator and tech | I35: No
B36: 46149 | C36: Days | D36: Labeller | E36: Sensor or controls | F36: Proximity sensor failed | G36: 75 | H36: Electrician | I36: No
B37: 46150 | C37: Earlies | D37: Depalletiser | E37: Sensor or controls | F37: PLC fault, reset and checked | G37: 17 | H37: Night tech | I37: No
B38: 46150 | C38: Lates | D38: Capper | E38: Material or supply | F38: Out of spec cases jammed | G38: 50 | H38: Night tech | I38: No
B39: 46153 | C39: Lates | D39: Labeller | E39: Mechanical | F39: Guide rail worked loose | G39: 24 | H39: Day tech | I39: No
B40: 46154 | C40: Earlies | D40: Conveyors | E40: Sensor or controls | F40: Photo eye misaligned | G40: 22 | H40: Day tech | I40: Yes
B41: 46155 | C41: Earlies | D41: Palletiser | E41: Mechanical | F41: Guide rail worked loose | G41: 33 | H41: Shift engineer | I41: No
B42: 46156 | C42: Days | D42: Filler | E42: Mechanical | F42: Gearbox coupling sheared | G42: 22 | H42: Electrician | I42: No
...

Sheet Setup
B1: SETUP
B2: Tell the dashboard about your line. Cream boxes only. The sample values are there to show you the format.
B5: YOUR LINE AND PERIOD
B6: Line or area name | C6: Line 3 (sample)
B7: Period start date | C7: 46113 | D7: The dashboard only counts breakdowns between these dates.
B8: Period end date | C8: 46295 | D8: Change both to look at a month, a quarter or a year.
B9: Planned run hours per day | C9: 21 | D9: Hours the line is meant to run, not counting planned stops.
B10: Run days per week | C10: 5
B11: Cost of an hour of downtime (£) | C11: 250 | D11: Ask what an hour of lost output is worth. If unsure, use labour cost as the floor.
B12: Planned run hours in this period | C12: =IF(OR(C7="",C8=""),0,(C8-C7+1)/7*N(C10)*N(C9)) -> 2745
B14: MACHINES (UP TO 15) | D14: FAILURE TYPES (UP TO 10)
B15: Depalletiser | D15: Mechanical | F15: These lists feed the dropdowns in the Breakdown Log and the charts on the Dashboard. Rename them to match your site.
B16: Filler | D16: Electrical
B17: Capper | D17: Pneumatic
B18: Labeller | D18: Sensor or controls
B19: Shrink wrapper | D19: Changeover or setup
B20: Case packer | D20: Material or supply
B21: Palletiser | D21: Other
B22: Conveyors

Sheet Workings
B1: WORKINGS
B2: The maths behind the Dashboard. Nothing to type here.
B5: BY MACHINE (setup order) | H5: BY MACHINE (worst first)
B6: Machine | C6: Breakdowns | D6: Minutes | E6: Sort key | G6: Rank | H6: Machine | I6: Minutes | J6: Hours | K6: Running % | L6: Breakdowns
B7: =IF(Setup!$B$15="","",Setup!$B$15) -> Depalletiser | C7: =IF(B7="",0,COUNTIFS('Breakdown Log'!$D$7:$D$506,B7,'Breakdown Log'!$B$7:$B$506,">="&Setup!$C$7,'Breakdown Log'!$B$7:$B$506,"<="&Setup!$C$8)) -> 6 | D7: =IF(B7="",0,SUMIFS('Breakdown Log'!$G$7:$G$506,'Breakdown Log'!$D$7:$D$506,B7,'Breakdown Log'!$B$7:$B$506,">="&Setup!$C$7,'Breakdown Log'!$B$7:$B$506,"<="&Setup!$C$8)) -> 168 | E7: =IF(B7="",-1,D7+(100-ROW())/1000) -> 168.093 | G7: 1 | H7: =IF(LARGE($E$7:$E$21,G7)<0,"",INDEX($B$7:$B$21,MATCH(LARGE($E$7:$E$21,G7),$E$7:$E$21,0))) -> Labeller | I7: =IF(H7="",0,INDEX($D$7:$D$21,MATCH(LARGE($E$7:$E$21,G7),$E$7:$E$21,0))) -> 1487 | J7: =I7/60 -> 24.783333 | K7: =IF(SUM($I$7:$I$21)=0,0,SUM($I$7:I7)/SUM($I$7:$I$21)) -> 0.33348284 | L7: =IF(H7="",0,INDEX($C$7:$C$21,MATCH(LARGE($E$7:$E$21,G7),$E$7:$E$21,0))) -> 31
B8: =IF(Setup!$B$16="","",Setup!$B$16) -> Filler | C8: =IF(B8="",0,COUNTIFS('Breakdown Log'!$D$7:$D$506,B8,'Breakdown Log'!$B$7:$B$506,">="&Setup!$C$7,'Breakdown Log'!$B$7:$B$506,"<="&Setup!$C$8)) -> 21 | D8: =IF(B8="",0,SUMIFS('Breakdown Log'!$G$7:$G$506,'Breakdown Log'!$D$7:$D$506,B8,'Breakdown Log'!$B$7:$B$506,">="&Setup!$C$7,'Breakdown Log'!$B$7:$B$506,"<="&Setup!$C$8)) -> 538 | E8: =IF(B8="",-1,D8+(100-ROW())/1000) -> 538.092 | G8: 2 | H8: =IF(LARGE($E$7:$E$21,G8)<0,"",INDEX($B$7:$B$21,MATCH(LARGE($E$7:$E$21,G8),$E$7:$E$21,0))) -> Filler | I8: =IF(H8="",0,INDEX($D$7:$D$21,MATCH(LARGE($E$7:$E$21,G8),$E$7:$E$21,0))) -> 538 | J8: =I8/60 -> 8.9666667 | K8: =IF(SUM($I$7:$I$21)=0,0,SUM($I$7:I8)/SUM($I$7:$I$21)) -> 0.4541377 | L8: =IF(H8="",0,INDEX($C$7:$C$21,MATCH(LARGE($E$7:$E$21,G8),$E$7:$E$21,0))) -> 21
B9: =IF(Setup!$B$17="","",Setup!$B$17) -> Capper | C9: =IF(B9="",0,COUNTIFS('Breakdown Log'!$D$7:$D$506,B9,'Breakdown Log'!$B$7:$B$506,">="&Setup!$C$7,'Breakdown Log'!$B$7:$B$506,"<="&Setup!$C$8)) -> 16 | D9: =IF(B9="",0,SUMIFS('Breakdown Log'!$G$7:$G$506,'Breakdown Log'!$D$7:$D$506,B9,'Breakdown Log'!$B$7:$B$506,">="&Setup!$C$7,'Breakdown Log'!$B$7:$B$506,"<="&Setup!$C$8)) -> 398 | E9: =IF(B9="",-1,D9+(100-ROW())/1000) -> 398.091 | G9: 3 | H9: =IF(LARGE($E$7:$E$21,G9)<0,"",INDEX($B$7:$B$21,MATCH(LARGE($E$7:$E$21,G9),$E$7:$E$21,0))) -> Case packer | I9: =IF(H9="",0,INDEX($D$7:$D$21,MATCH(LARGE($E$7:$E$21,G9),$E$7:$E$21,0))) -> 518 | J9: =I9/60 -> 8.6333333 | K9: =IF(SUM($I$7:$I$21)=0,0,SUM($I$7:I9)/SUM($I$7:$I$21)) -> 0.57030724 | L9: =IF(H9="",0,INDEX($C$7:$C$21,MATCH(LARGE($E$7:$E$21,G9),$E$7:$E$21,0))) -> 18
B10: =IF(Setup!$B$18="","",Setup!$B$18) -> Labeller | C10: =IF(B10="",0,COUNTIFS('Breakdown Log'!$D$7:$D$506,B10,'Breakdown Log'!$B$7:$B$506,">="&Setup!$C$7,'Breakdown Log'!$B$7:$B$506,"<="&Setup!$C$8)) -> 31 | D10: =IF(B10="",0,SUMIFS('Breakdown Log'!$G$7:$G$506,'Breakdown Log'!$D$7:$D$506,B10,'Breakdown Log'!$B$7:$B$506,">="&Setup!$C$7,'Breakdown Log'!$B$7:$B$506,"<="&Setup!$C$8)) -> 1487 | E10: =IF(B10="",-1,D10+(100-ROW())/1000) -> 1487.09 | G10: 4 | H10: =IF(LARGE($E$7:$E$21,G10)<0,"",INDEX($B$7:$B$21,MATCH(LARGE($E$7:$E$21,G10),$E$7:$E$21,0))) -> Palletiser | I10: =IF(H10="",0,INDEX($D$7:$D$21,MATCH(LARGE($E$7:$E$21,G10),$E$7:$E$21,0))) -> 505 | J10: =I10/60 -> 8.4166667 | K10: =IF(SUM($I$7:$I$21)=0,0,SUM($I$7:I10)/SUM($I$7:$I$21)) -> 0.68356134 | L10: =IF(H10="",0,INDEX($C$7:$C$21,MATCH(LARGE($E$7:$E$21,G10),$E$7:$E$21,0))) -> 14
B11: =IF(Setup!$B$19="","",Setup!$B$19) -> Shrink wrapper | C11: =IF(B11="",0,COUNTIFS('Breakdown Log'!$D$7:$D$506,B11,'Breakdown Log'!$B$7:$B$506,">="&Setup!$C$7,'Breakdown Log'!$B$7:$B$506,"<="&Setup!$C$8)) -> 15 | D11: =IF(B11="",0,SUMIFS('Breakdown Log'!$G$7:$G$506,'Breakdown Log'!$D$7:$D$506,B11,'Breakdown Log'!$B$7:$B$506,">="&Setup!$C$7,'Breakdown Log'!$B$7:$B$506,"<="&Setup!$C$8)) -> 471 | E11: =IF(B11="",-1,D11+(100-ROW())/1000) -> 471.089 | G11: 5 | H11: =IF(LARGE($E$7:$E$21,G11)<0,"",INDEX($B$7:$B$21,MATCH(LARGE($E$7:$E$21,G11),$E$7:$E$21,0))) -> Shrink wrapper | I11: =IF(H11="",0,INDEX($D$7:$D$21,MATCH(LARGE($E$7:$E$21,G11),$E$7:$E$21,0))) -> 471 | J11: =I11/60 -> 7.85 | K11: =IF(SUM($I$7:$I$21)=0,0,SUM($I$7:I11)/SUM($I$7:$I$21)) -> 0.7891904 | L11: =IF(H11="",0,INDEX($C$7:$C$21,MATCH(LARGE($E$7:$E$21,G11),$E$7:$E$21,0))) -> 15
B12: =IF(Setup!$B$20="","",Setup!$B$20) -> Case packer | C12: =IF(B12="",0,COUNTIFS('Breakdown Log'!$D$7:$D$506,B12,'Breakdown Log'!$B$7:$B$506,">="&Setup!$C$7,'Breakdown Log'!$B$7:$B$506,"<="&Setup!$C$8)) -> 18 | D12: =IF(B12="",0,SUMIFS('Breakdown Log'!$G$7:$G$506,'Breakdown Log'!$D$7:$D$506,B12,'Breakdown Log'!$B$7:$B$506,">="&Setup!$C$7,'Breakdown Log'!$B$7:$B$506,"<="&Setup!$C$8)) -> 518 | E12: =IF(B12="",-1,D12+(100-ROW())/1000) -> 518.088 | G12: 6 | H12: =IF(LARGE($E$7:$E$21,G12)<0,"",INDEX($B$7:$B$21,MATCH(LARGE($E$7:$E$21,G12),$E$7:$E$21,0))) -> Capper | I12: =IF(H12="",0,INDEX($D$7:$D$21,MATCH(LARGE($E$7:$E$21,G12),$E$7:$E$21,0))) -> 398 | J12: =I12/60 -> 6.6333333 | K12: =IF(SUM($I$7:$I$21)=0,0,SUM($I$7:I12)/SUM($I$7:$I$21)) -> 0.87844808 | L12: =IF(H12="",0,INDEX($C$7:$C$21,MATCH(LARGE($E$7:$E$21,G12),$E$7:$E$21,0))) -> 16
B13: =IF(Setup!$B$21="","",Setup!$B$21) -> Palletiser | C13: =IF(B13="",0,COUNTIFS('Breakdown Log'!$D$7:$D$506,B13,'Breakdown Log'!$B$7:$B$506,">="&Setup!$C$7,'Breakdown Log'!$B$7:$B$506,"<="&Setup!$C$8)) -> 14 | D13: =IF(B13="",0,SUMIFS('Breakdown Log'!$G$7:$G$506,'Breakdown Log'!$D$7:$D$506,B13,'Breakdown Log'!$B$7:$B$506,">="&Setup!$C$7,'Breakdown Log'!$B$7:$B$506,"<="&Setup!$C$8)) -> 505 | E13: =IF(B13="",-1,D13+(100-ROW())/1000) -> 505.087 | G13: 7 | H13: =IF(LARGE($E$7:$E$21,G13)<0,"",INDEX($B$7:$B$21,MATCH(LARGE($E$7:$E$21,G13),$E$7:$E$21,0))) -> Conveyors | I13: =IF(H13="",0,INDEX($D$7:$D$21,MATCH(LARGE($E$7:$E$21,G13),$E$7:$E$21,0))) -> 374 | J13: =I13/60 -> 6.2333333 | K13: =IF(SUM($I$7:$I$21)=0,0,SUM($I$7:I13)/SUM($I$7:$I$21)) -> 0.96232339 | L13: =IF(H13="",0,INDEX($C$7:$C$21,MATCH(LARGE($E$7:$E$21,G13),$E$7:$E$21,0))) -> 11
B14: =IF(Setup!$B$22="","",Setup!$B$22) -> Conveyors | C14: =IF(B14="",0,COUNTIFS('Breakdown Log'!$D$7:$D$506,B14,'Breakdown Log'!$B$7:$B$506,">="&Setup!$C$7,'Breakdown Log'!$B$7:$B$506,"<="&Setup!$C$8)) -> 11 | D14: =IF(B14="",0,SUMIFS('Breakdown Log'!$G$7:$G$506,'Breakdown Log'!$D$7:$D$506,B14,'Breakdown Log'!$B$7:$B$506,">="&Setup!$C$7,'Breakdown Log'!$B$7:$B$506,"<="&Setup!$C$8)) -> 374 | E14: =IF(B14="",-1,D14+(100-ROW())/1000) -> 374.086 | G14: 8 | H14: =IF(LARGE($E$7:$E$21,G14)<0,"",INDEX($B$7:$B$21,MATCH(LARGE($E$7:$E$21,G14),$E$7:$E$21,0))) -> Depalletiser | I14: =IF(H14="",0,INDEX($D$7:$D$21,MATCH(LARGE($E$7:$E$21,G14),$E$7:$E$21,0))) -> 168 | J14: =I14/60 -> 2.8 | K14: =IF(SUM($I$7:$I$21)=0,0,SUM($I$7:I14)/SUM($I$7:$I$21)) -> 1 | L14: =IF(H14="",0,INDEX($C$7:$C$21,MATCH(LARGE($E$7:$E$21,G14),$E$7:$E$21,0))) -> 6
B15: =IF(Setup!$B$23="","",Setup!$B$23) | C15: =IF(B15="",0,COUNTIFS('Breakdown Log'!$D$7:$D$506,B15,'Breakdown Log'!$B$7:$B$506,">="&Setup!$C$7,'Breakdown Log'!$B$7:$B$506,"<="&Setup!$C$8)) -> 0 | D15: =IF(B15="",0,SUMIFS('Breakdown Log'!$G$7:$G$506,'Breakdown Log'!$D$7:$D$506,B15,'Breakdown Log'!$B$7:$B$506,">="&Setup!$C$7,'Breakdown Log'!$B$7:$B$506,"<="&Setup!$C$8)) -> 0 | E15: =IF(B15="",-1,D15+(100-ROW())/1000) -> -1 | G15: 9 | H15: =IF(LARGE($E$7:$E$21,G15)<0,"",INDEX($B$7:$B$21,MATCH(LARGE($E$7:$E$21,G15),$E$7:$E$21,0))) | I15: =IF(H15="",0,INDEX($D$7:$D$21,MATCH(LARGE($E$7:$E$21,G15),$E$7:$E$21,0))) -> 0 | J15: =I15/60 -> 0 | K15: =IF(SUM($I$7:$I$21)=0,0,SUM($I$7:I15)/SUM($I$7:$I$21)) -> 1 | L15: =IF(H15="",0,INDEX($C$7:$C$21,MATCH(LARGE($E$7:$E$21,G15),$E$7:$E$21,0))) -> 0
B16: =IF(Setup!$B$24="","",Setup!$B$24) | C16: =IF(B16="",0,COUNTIFS('Breakdown Log'!$D$7:$D$506,B16,'Breakdown Log'!$B$7:$B$506,">="&Setup!$C$7,'Breakdown Log'!$B$7:$B$506,"<="&Setup!$C$8)) -> 0 | D16: =IF(B16="",0,SUMIFS('Breakdown Log'!$G$7:$G$506,'Breakdown Log'!$D$7:$D$506,B16,'Breakdown Log'!$B$7:$B$506,">="&Setup!$C$7,'Breakdown Log'!$B$7:$B$506,"<="&Setup!$C$8)) -> 0 | E16: =IF(B16="",-1,D16+(100-ROW())/1000) -> -1 | G16: 10 | H16: =IF(LARGE($E$7:$E$21,G16)<0,"",INDEX($B$7:$B$21,MATCH(LARGE($E$7:$E$21,G16),$E$7:$E$21,0))) | I16: =IF(H16="",0,INDEX($D$7:$D$21,MATCH(LARGE($E$7:$E$21,G16),$E$7:$E$21,0))) -> 0 | J16: =I16/60 -> 0 | K16: =IF(SUM($I$7:$I$21)=0,0,SUM($I$7:I16)/SUM($I$7:$I$21)) -> 1 | L16: =IF(H16="",0,INDEX($C$7:$C$21,MATCH(LARGE($E$7:$E$21,G16),$E$7:$E$21,0))) -> 0
B17: =IF(Setup!$B$25="","",Setup!$B$25) | C17: =IF(B17="",0,COUNTIFS('Breakdown Log'!$D$7:$D$506,B17,'Breakdown Log'!$B$7:$B$506,">="&Setup!$C$7,'Breakdown Log'!$B$7:$B$506,"<="&Setup!$C$8)) -> 0 | D17: =IF(B17="",0,SUMIFS('Breakdown Log'!$G$7:$G$506,'Breakdown Log'!$D$7:$D$506,B17,'Breakdown Log'!$B$7:$B$506,">="&Setup!$C$7,'Breakdown Log'!$B$7:$B$506,"<="&Setup!$C$8)) -> 0 | E17: =IF(B17="",-1,D17+(100-ROW())/1000) -> -1 | G17: 11 | H17: =IF(LARGE($E$7:$E$21,G17)<0,"",INDEX($B$7:$B$21,MATCH(LARGE($E$7:$E$21,G17),$E$7:$E$21,0))) | I17: =IF(H17="",0,INDEX($D$7:$D$21,MATCH(LARGE($E$7:$E$21,G17),$E$7:$E$21,0))) -> 0 | J17: =I17/60 -> 0 | K17: =IF(SUM($I$7:$I$21)=0,0,SUM($I$7:I17)/SUM($I$7:$I$21)) -> 1 | L17: =IF(H17="",0,INDEX($C$7:$C$21,MATCH(LARGE($E$7:$E$21,G17),$E$7:$E$21,0))) -> 0
B18: =IF(Setup!$B$26="","",Setup!$B$26) | C18: =IF(B18="",0,COUNTIFS('Breakdown Log'!$D$7:$D$506,B18,'Breakdown Log'!$B$7:$B$506,">="&Setup!$C$7,'Breakdown Log'!$B$7:$B$506,"<="&Setup!$C$8)) -> 0 | D18: =IF(B18="",0,SUMIFS('Breakdown Log'!$G$7:$G$506,'Breakdown Log'!$D$7:$D$506,B18,'Breakdown Log'!$B$7:$B$506,">="&Setup!$C$7,'Breakdown Log'!$B$7:$B$506,"<="&Setup!$C$8)) -> 0 | E18: =IF(B18="",-1,D18+(100-ROW())/1000) -> -1 | G18: 12 | H18: =IF(LARGE($E$7:$E$21,G18)<0,"",INDEX($B$7:$B$21,MATCH(LARGE($E$7:$E$21,G18),$E$7:$E$21,0))) | I18: =IF(H18="",0,INDEX($D$7:$D$21,MATCH(LARGE($E$7:$E$21,G18),$E$7:$E$21,0))) -> 0 | J18: =I18/60 -> 0 | K18: =IF(SUM($I$7:$I$21)=0,0,SUM($I$7:I18)/SUM($I$7:$I$21)) -> 1 | L18: =IF(H18="",0,INDEX($C$7:$C$21,MATCH(LARGE($E$7:$E$21,G18),$E$7:$E$21,0))) -> 0
B19: =IF(Setup!$B$27="","",Setup!$B$27) | C19: =IF(B19="",0,COUNTIFS('Breakdown Log'!$D$7:$D$506,B19,'Breakdown Log'!$B$7:$B$506,">="&Setup!$C$7,'Breakdown Log'!$B$7:$B$506,"<="&Setup!$C$8)) -> 0 | D19: =IF(B19="",0,SUMIFS('Breakdown Log'!$G$7:$G$506,'Breakdown Log'!$D$7:$D$506,B19,'Breakdown Log'!$B$7:$B$506,">="&Setup!$C$7,'Breakdown Log'!$B$7:$B$506,"<="&Setup!$C$8)) -> 0 | E19: =IF(B19="",-1,D19+(100-ROW())/1000) -> -1 | G19: 13 | H19: =IF(LARGE($E$7:$E$21,G19)<0,"",INDEX($B$7:$B$21,MATCH(LARGE($E$7:$E$21,G19),$E$7:$E$21,0))) | I19: =IF(H19="",0,INDEX($D$7:$D$21,MATCH(LARGE($E$7:$E$21,G19),$E$7:$E$21,0))) -> 0 | J19: =I19/60 -> 0 | K19: =IF(SUM($I$7:$I$21)=0,0,SUM($I$7:I19)/SUM($I$7:$I$21)) -> 1 | L19: =IF(H19="",0,INDEX($C$7:$C$21,MATCH(LARGE($E$7:$E$21,G19),$E$7:$E$21,0))) -> 0
B20: =IF(Setup!$B$28="","",Setup!$B$28) | C20: =IF(B20="",0,COUNTIFS('Breakdown Log'!$D$7:$D$506,B20,'Breakdown Log'!$B$7:$B$506,">="&Setup!$C$7,'Breakdown Log'!$B$7:$B$506,"<="&Setup!$C$8)) -> 0 | D20: =IF(B20="",0,SUMIFS('Breakdown Log'!$G$7:$G$506,'Breakdown Log'!$D$7:$D$506,B20,'Breakdown Log'!$B$7:$B$506,">="&Setup!$C$7,'Breakdown Log'!$B$7:$B$506,"<="&Setup!$C$8)) -> 0 | E20: =IF(B20="",-1,D20+(100-ROW())/1000) -> -1 | G20: 14 | H20: =IF(LARGE($E$7:$E$21,G20)<0,"",INDEX($B$7:$B$21,MATCH(LARGE($E$7:$E$21,G20),$E$7:$E$21,0))) | I20: =IF(H20="",0,INDEX($D$7:$D$21,MATCH(LARGE($E$7:$E$21,G20),$E$7:$E$21,0))) -> 0 | J20: =I20/60 -> 0 | K20: =IF(SUM($I$7:$I$21)=0,0,SUM($I$7:I20)/SUM($I$7:$I$21)) -> 1 | L20: =IF(H20="",0,INDEX($C$7:$C$21,MATCH(LARGE($E$7:$E$21,G20),$E$7:$E$21,0))) -> 0
B21: =IF(Setup!$B$29="","",Setup!$B$29) | C21: =IF(B21="",0,COUNTIFS('Breakdown Log'!$D$7:$D$506,B21,'Breakdown Log'!$B$7:$B$506,">="&Setup!$C$7,'Breakdown Log'!$B$7:$B$506,"<="&Setup!$C$8)) -> 0 | D21: =IF(B21="",0,SUMIFS('Breakdown Log'!$G$7:$G$506,'Breakdown Log'!$D$7:$D$506,B21,'Breakdown Log'!$B$7:$B$506,">="&Setup!$C$7,'Breakdown Log'!$B$7:$B$506,"<="&Setup!$C$8)) -> 0 | E21: =IF(B21="",-1,D21+(100-ROW())/1000) -> -1 | G21: 15 | H21: =IF(LARGE($E$7:$E$21,G21)<0,"",INDEX($B$7:$B$21,MATCH(LARGE($E$7:$E$21,G21),$E$7:$E$21,0))) | I21: =IF(H21="",0,INDEX($D$7:$D$21,MATCH(LARGE($E$7:$E$21,G21),$E$7:$E$21,0))) -> 0 | J21: =I21/60 -> 0 | K21: =IF(SUM($I$7:$I$21)=0,0,SUM($I$7:I21)/SUM($I$7:$I$21)) -> 1 | L21: =IF(H21="",0,INDEX($C$7:$C$21,MATCH(LARGE($E$7:$E$21,G21),$E$7:$E$21,0))) -> 0
B24: BY FAILURE TYPE (setup order) | H24: BY FAILURE TYPE (worst first)
B25: Failure type | C25: Breakdowns | D25: Minutes | E25: Sort key | G25: Rank | H25: Failure type | I25: Minutes | J25: Hours | K25: Running % | L25: Breakdowns
B26: =IF(Setup!$D$15="","",Setup!$D$15) -> Mechanical | C26: =IF(B26="",0,COUNTIFS('Breakdown Log'!$E$7:$E$506,B26,'Breakdown Log'!$B$7:$B$506,">="&Setup!$C$7,'Breakdown Log'!$B$7:$B$506,"<="&Setup!$C$8)) -> 39 | D26: =IF(B26="",0,SUMIFS('Breakdown Log'!$G$7:$G$506,'Breakdown Log'!$E$7:$E$506,B26,'Breakdown Log'!$B$7:$B$506,">="&Setup!$C$7,'Breakdown Log'!$B$7:$B$506,"<="&Setup!$C$8)) -> 1376 | E26: =IF(B26="",-1,D26+(100-ROW())/1000) -> 1376.074 | G26: 1 | H26: =IF(LARGE($E$26:$E$35,G26)<0,"",INDEX($B$26:$B$35,MATCH(LARGE($E$26:$E$35,G26),$E$26:$E$35,0))) -> Mechanical | I26: =IF(H26="",0,INDEX($D$26:$D$35,MATCH(LARGE($E$26:$E$35,G26),$E$26:$E$35,0))) -> 1376 | J26: =I26/60 -> 22.933333 | K26: =IF(SUM($I$26:$I$35)=0,0,SUM($I$26:I26)/SUM($I$26:$I$35)) -> 0.30858937 | L26: =IF(H26="",0,INDEX($C$26:$C$35,MATCH(LARGE($E$26:$E$35,G26),$E$26:$E$35,0))) -> 39
B27: =IF(Setup!$D$16="","",Setup!$D$16) -> Electrical | C27: =IF(B27="",0,COUNTIFS('Breakdown Log'!$E$7:$E$506,B27,'Breakdown Log'!$B$7:$B$506,">="&Setup!$C$7,'Breakdown Log'!$B$7:$B$506,"<="&Setup!$C$8)) -> 11 | D27: =IF(B27="",0,SUMIFS('Breakdown Log'!$G$7:$G$506,'Breakdown Log'!$E$7:$E$506,B27,'Breakdown Log'!$B$7:$B$506,">="&Setup!$C$7,'Breakdown Log'!$B$7:$B$506,"<="&Setup!$C$8)) -> 199 | E27: =IF(B27="",-1,D27+(100-ROW())/1000) -> 199.073 | G27: 2 | H27: =IF(LARGE($E$26:$E$35,G27)<0,"",INDEX($B$26:$B$35,MATCH(LARGE($E$26:$E$35,G27),$E$26:$E$35,0))) -> Material or supply | I27: =IF(H27="",0,INDEX($D$26:$D$35,MATCH(LARGE($E$26:$E$35,G27),$E$26:$E$35,0))) -> 973 | J27: =I27/60 -> 16.216667 | K27: =IF(SUM($I$26:$I$35)=0,0,SUM($I$26:I27)/SUM($I$26:$I$35)) -> 0.52679973 | L27: =IF(H27="",0,INDEX($C$26:$C$35,MATCH(LARGE($E$26:$E$35,G27),$E$26:$E$35,0))) -> 24
B28: =IF(Setup!$D$17="","",Setup!$D$17) -> Pneumatic | C28: =IF(B28="",0,COUNTIFS('Breakdown Log'!$E$7:$E$506,B28,'Breakdown Log'!$B$7:$B$506,">="&Setup!$C$7,'Breakdown Log'!$B$7:$B$506,"<="&Setup!$C$8)) -> 11 | D28: =IF(B28="",0,SUMIFS('Breakdown Log'!$G$7:$G$506,'Breakdown Log'!$E$7:$E$506,B28,'Breakdown Log'!$B$7:$B$506,">="&Setup!$C$7,'Breakdown Log'!$B$7:$B$506,"<="&Setup!$C$8)) -> 255 | E28: =IF(B28="",-1,D28+(100-ROW())/1000) -> 255.072 | G28: 3 | H28: =IF(LARGE($E$26:$E$35,G28)<0,"",INDEX($B$26:$B$35,MATCH(LARGE($E$26:$E$35,G28),$E$26:$E$35,0))) -> Sensor or controls | I28: =IF(H28="",0,INDEX($D$26:$D$35,MATCH(LARGE($E$26:$E$35,G28),$E$26:$E$35,0))) -> 942 | J28: =I28/60 -> 15.7 | K28: =IF(SUM($I$26:$I$35)=0,0,SUM($I$26:I28)/SUM($I$26:$I$35)) -> 0.73805786 | L28: =IF(H28="",0,INDEX($C$26:$C$35,MATCH(LARGE($E$26:$E$35,G28),$E$26:$E$35,0))) -> 26
B29: =IF(Setup!$D$18="","",Setup!$D$18) -> Sensor or controls | C29: =IF(B29="",0,COUNTIFS('Breakdown Log'!$E$7:$E$506,B29,'Breakdown Log'!$B$7:$B$506,">="&Setup!$C$7,'Breakdown Log'!$B$7:$B$506,"<="&Setup!$C$8)) -> 26 | D29: =IF(B29="",0,SUMIFS('Breakdown Log'!$G$7:$G$506,'Breakdown Log'!$E$7:$E$506,B29,'Breakdown Log'!$B$7:$B$506,">="&Setup!$C$7,'Breakdown Log'!$B$7:$B$506,"<="&Setup!$C$8)) -> 942 | E29: =IF(B29="",-1,D29+(100-ROW())/1000) -> 942.071 | G29: 4 | H29: =IF(LARGE($E$26:$E$35,G29)<0,"",INDEX($B$26:$B$35,MATCH(LARGE($E$26:$E$35,G29),$E$26:$E$35,0))) -> Other | I29: =IF(H29="",0,INDEX($D$26:$D$35,MATCH(LARGE($E$26:$E$35,G29),$E$26:$E$35,0))) -> 404 | J29: =I29/60 -> 6.7333333 | K29: =IF(SUM($I$26:$I$35)=0,0,SUM($I$26:I29)/SUM($I$26:$I$35)) -> 0.82866113 | L29: =IF(H29="",0,INDEX($C$26:$C$35,MATCH(LARGE($E$26:$E$35,G29),$E$26:$E$35,0))) -> 9
B30: =IF(Setup!$D$19="","",Setup!$D$19) -> Changeover or setup | C30: =IF(B30="",0,COUNTIFS('Breakdown Log'!$E$7:$E$506,B30,'Breakdown Log'!$B$7:$B$506,">="&Setup!$C$7,'Breakdown Log'!$B$7:$B$506,"<="&Setup!$C$8)) -> 12 | D30: =IF(B30="",0,SUMIFS('Breakdown Log'!$G$7:$G$506,'Breakdown Log'!$E$7:$E$506,B30,'Breakdown Log'!$B$7:$B$506,">="&Setup!$C$7,'Breakdown Log'!$B$7:$B$506,"<="&Setup!$C$8)) -> 310 | E30: =IF(B30="",-1,D30+(100-ROW())/1000) -> 310.07 | G30: 5 | H30: =IF(LARGE($E$26:$E$35,G30)<0,"",INDEX($B$26:$B$35,MATCH(LARGE($E$26:$E$35,G30),$E$26:$E$35,0))) -> Changeover or setup | I30: =IF(H30="",0,INDEX($D$26:$D$35,MATCH(LARGE($E$26:$E$35,G30),$E$26:$E$35,0))) -> 310 | J30: =I30/60 -> 5.1666667 | K30: =IF(SUM($I$26:$I$35)=0,0,SUM($I$26:I30)/SUM($I$26:$I$35)) -> 0.89818345 | L30: =IF(H30="",0,INDEX($C$26:$C$35,MATCH(LARGE($E$26:$E$35,G30),$E$26:$E$35,0))) -> 12
B31: =IF(Setup!$D$20="","",Setup!$D$20) -> Material or supply | C31: =IF(B31="",0,COUNTIFS('Breakdown Log'!$E$7:$E$506,B31,'Breakdown Log'!$B$7:$B$506,">="&Setup!$C$7,'Breakdown Log'!$B$7:$B$506,"<="&Setup!$C$8)) -> 24 | D31: =IF(B31="",0,SUMIFS('Breakdown Log'!$G$7:$G$506,'Breakdown Log'!$E$7:$E$506,B31,'Breakdown Log'!$B$7:$B$506,">="&Setup!$C$7,'Breakdown Log'!$B$7:$B$506,"<="&Setup!$C$8)) -> 973 | E31: =IF(B31="",-1,D31+(100-ROW())/1000) -> 973.069 | G31: 6 | H31: =IF(LARGE($E$26:$E$35,G31)<0,"",INDEX($B$26:$B$35,MATCH(LARGE($E$26:$E$35,G31),$E$26:$E$35,0))) -> Pneumatic | I31: =IF(H31="",0,INDEX($D$26:$D$35,MATCH(LARGE($E$26:$E$35,G31),$E$26:$E$35,0))) -> 255 | J31: =I31/60 -> 4.25 | K31: =IF(SUM($I$26:$I$35)=0,0,SUM($I$26:I31)/SUM($I$26:$I$35)) -> 0.95537116 | L31: =IF(H31="",0,INDEX($C$26:$C$35,MATCH(LARGE($E$26:$E$35,G31),$E$26:$E$35,0))) -> 11
B32: =IF(Setup!$D$21="","",Setup!$D$21) -> Other | C32: =IF(B32="",0,COUNTIFS('Breakdown Log'!$E$7:$E$506,B32,'Breakdown Log'!$B$7:$B$506,">="&Setup!$C$7,'Breakdown Log'!$B$7:$B$506,"<="&Setup!$C$8)) -> 9 | D32: =IF(B32="",0,SUMIFS('Breakdown Log'!$G$7:$G$506,'Breakdown Log'!$E$7:$E$506,B32,'Breakdown Log'!$B$7:$B$506,">="&Setup!$C$7,'Breakdown Log'!$B$7:$B$506,"<="&Setup!$C$8)) -> 404 | E32: =IF(B32="",-1,D32+(100-ROW())/1000) -> 404.068 | G32: 7 | H32: =IF(LARGE($E$26:$E$35,G32)<0,"",INDEX($B$26:$B$35,MATCH(LARGE($E$26:$E$35,G32),$E$26:$E$35,0))) -> Electrical | I32: =IF(H32="",0,INDEX($D$26:$D$35,MATCH(LARGE($E$26:$E$35,G32),$E$26:$E$35,0))) -> 199 | J32: =I32/60 -> 3.3166667 | K32: =IF(SUM($I$26:$I$35)=0,0,SUM($I$26:I32)/SUM($I$26:$I$35)) -> 1 | L32: =IF(H32="",0,INDEX($C$26:$C$35,MATCH(LARGE($E$26:$E$35,G32),$E$26:$E$35,0))) -> 11
B33: =IF(Setup!$D$22="","",Setup!$D$22) | C33: =IF(B33="",0,COUNTIFS('Breakdown Log'!$E$7:$E$506,B33,'Breakdown Log'!$B$7:$B$506,">="&Setup!$C$7,'Breakdown Log'!$B$7:$B$506,"<="&Setup!$C$8)) -> 0 | D33: =IF(B33="",0,SUMIFS('Breakdown Log'!$G$7:$G$506,'Breakdown Log'!$E$7:$E$506,B33,'Breakdown Log'!$B$7:$B$506,">="&Setup!$C$7,'Breakdown Log'!$B$7:$B$506,"<="&Setup!$C$8)) -> 0 | E33: =IF(B33="",-1,D33+(100-ROW())/1000) -> -1 | G33: 8 | H33: =IF(LARGE($E$26:$E$35,G33)<0,"",INDEX($B$26:$B$35,MATCH(LARGE($E$26:$E$35,G33),$E$26:$E$35,0))) | I33: =IF(H33="",0,INDEX($D$26:$D$35,MATCH(LARGE($E$26:$E$35,G33),$E$26:$E$35,0))) -> 0 | J33: =I33/60 -> 0 | K33: =IF(SUM($I$26:$I$35)=0,0,SUM($I$26:I33)/SUM($I$26:$I$35)) -> 1 | L33: =IF(H33="",0,INDEX($C$26:$C$35,MATCH(LARGE($E$26:$E$35,G33),$E$26:$E$35,0))) -> 0
B34: =IF(Setup!$D$23="","",Setup!$D$23) | C34: =IF(B34="",0,COUNTIFS('Breakdown Log'!$E$7:$E$506,B34,'Breakdown Log'!$B$7:$B$506,">="&Setup!$C$7,'Breakdown Log'!$B$7:$B$506,"<="&Setup!$C$8)) -> 0 | D34: =IF(B34="",0,SUMIFS('Breakdown Log'!$G$7:$G$506,'Breakdown Log'!$E$7:$E$506,B34,'Breakdown Log'!$B$7:$B$506,">="&Setup!$C$7,'Breakdown Log'!$B$7:$B$506,"<="&Setup!$C$8)) -> 0 | E34: =IF(B34="",-1,D34+(100-ROW())/1000) -> -1 | G34: 9 | H34: =IF(LARGE($E$26:$E$35,G34)<0,"",INDEX($B$26:$B$35,MATCH(LARGE($E$26:$E$35,G34),$E$26:$E$35,0))) | I34: =IF(H34="",0,INDEX($D$26:$D$35,MATCH(LARGE($E$26:$E$35,G34),$E$26:$E$35,0))) -> 0 | J34: =I34/60 -> 0 | K34: =IF(SUM($I$26:$I$35)=0,0,SUM($I$26:I34)/SUM($I$26:$I$35)) -> 1 | L34: =IF(H34="",0,INDEX($C$26:$C$35,MATCH(LARGE($E$26:$E$35,G34),$E$26:$E$35,0))) -> 0
B35: =IF(Setup!$D$24="","",Setup!$D$24) | C35: =IF(B35="",0,COUNTIFS('Breakdown Log'!$E$7:$E$506,B35,'Breakdown Log'!$B$7:$B$506,">="&Setup!$C$7,'Breakdown Log'!$B$7:$B$506,"<="&Setup!$C$8)) -> 0 | D35: =IF(B35="",0,SUMIFS('Breakdown Log'!$G$7:$G$506,'Breakdown Log'!$E$7:$E$506,B35,'Breakdown Log'!$B$7:$B$506,">="&Setup!$C$7,'Breakdown Log'!$B$7:$B$506,"<="&Setup!$C$8)) -> 0 | E35: =IF(B35="",-1,D35+(100-ROW())/1000) -> -1 | G35: 10 | H35: =IF(LARGE($E$26:$E$35,G35)<0,"",INDEX($B$26:$B$35,MATCH(LARGE($E$26:$E$35,G35),$E$26:$E$35,0))) | I35: =IF(H35="",0,INDEX($D$26:$D$35,MATCH(LARGE($E$26:$E$35,G35),$E$26:$E$35,0))) -> 0 | J35: =I35/60 -> 0 | K35: =IF(SUM($I$26:$I$35)=0,0,SUM($I$26:I35)/SUM($I$26:$I$35)) -> 1 | L35: =IF(H35="",0,INDEX($C$26:$C$35,MATCH(LARGE($E$26:$E$35,G35),$E$26:$E$35,0))) -> 0
B38: BY MONTH | H38: BY SHIFT
B39: Month start | C39: Breakdowns | D39: Hours down | E39: Label | H39: Shift | I39: Breakdowns | J39: Hours down
B40: =DATE(YEAR(Setup!$C$7),MONTH(Setup!$C$7),1) -> 46113 | C40: =COUNTIFS('Breakdown Log'!$B$7:$B$506,">="&B40,'Breakdown Log'!$B$7:$B$506,"<"&EDATE(B40,1),'Breakdown Log'!$B$7:$B$506,">="&Setup!$C$7,'Breakdown Log'!$B$7:$B$506,"<="&Setup!$C$8) -> 24 | D40: =SUMIFS('Breakdown Log'!$G$7:$G$506,'Breakdown Log'!$B$7:$B$506,">="&B40,'Breakdown Log'!$B$7:$B$506,"<"&EDATE(B40,1),'Breakdown Log'!$B$7:$B$506,">="&Setup!$C$7,'Breakdown Log'!$B$7:$B$506,"<="&Setup!$C$8)/60 -> 11.983333 | E40: =TEXT(B40,"mmm yy") -> Apr 26 | H40: Days | I40: =COUNTIFS('Breakdown Log'!$C$7:$C$506,H40,'Breakdown Log'!$B$7:$B$506,">="&Setup!$C$7,'Breakdown Log'!$B$7:$B$506,"<="&Setup!$C$8) -> 30 | J40: =SUMIFS('Breakdown Log'!$G$7:$G$506,'Breakdown Log'!$C$7:$C$506,H40,'Breakdown Log'!$B$7:$B$506,">="&Setup!$C$7,'Breakdown Log'!$B$7:$B$506,"<="&Setup!$C$8)/60 -> 16.983333
B41: =EDATE(B40,1) -> 46143 | C41: =COUNTIFS('Breakdown Log'!$B$7:$B$506,">="&B41,'Breakdown Log'!$B$7:$B$506,"<"&EDATE(B41,1),'Breakdown Log'!$B$7:$B$506,">="&Setup!$C$7,'Breakdown Log'!$B$7:$B$506,"<="&Setup!$C$8) -> 24 | D41: =SUMIFS('Breakdown Log'!$G$7:$G$506,'Breakdown Log'!$B$7:$B$506,">="&B41,'Breakdown Log'!$B$7:$B$506,"<"&EDATE(B41,1),'Breakdown Log'!$B$7:$B$506,">="&Setup!$C$7,'Breakdown Log'!$B$7:$B$506,"<="&Setup!$C$8)/60 -> 15.25 | E41: =TEXT(B41,"mmm yy") -> May 26 | H41: Earlies | I41: =COUNTIFS('Breakdown Log'!$C$7:$C$506,H41,'Breakdown Log'!$B$7:$B$506,">="&Setup!$C$7,'Breakdown Log'!$B$7:$B$506,"<="&Setup!$C$8) -> 34 | J41: =SUMIFS('Breakdown Log'!$G$7:$G$506,'Breakdown Log'!$C$7:$C$506,H41,'Breakdown Log'!$B$7:$B$506,">="&Setup!$C$7,'Breakdown Log'!$B$7:$B$506,"<="&Setup!$C$8)/60 -> 19.516667
B42: =EDATE(B41,1) -> 46174 | C42: =COUNTIFS('Breakdown Log'!$B$7:$B$506,">="&B42,'Breakdown Log'!$B$7:$B$506,"<"&EDATE(B42,1),'Breakdown Log'!$B$7:$B$506,">="&Setup!$C$7,'Breakdown Log'!$B$7:$B$506,"<="&Setup!$C$8) -> 26 | D42: =SUMIFS('Breakdown Log'!$G$7:$G$506,'Breakdown Log'!$B$7:$B$506,">="&B42,'Breakdown Log'!$B$7:$B$506,"<"&EDATE(B42,1),'Breakdown Log'!$B$7:$B$506,">="&Setup!$C$7,'Breakdown Log'!$B$7:$B$506,"<="&Setup!$C$8)/60 -> 16.883333 | E42: =TEXT(B42,"mmm yy") -> Jun 26 | H42: Lates | I42: =COUNTIFS('Breakdown Log'!$C$7:$C$506,H42,'Breakdown Log'!$B$7:$B$506,">="&Setup!$C$7,'Breakdown Log'!$B$7:$B$506,"<="&Setup!$C$8) -> 39 | J42: =SUMIFS('Breakdown Log'!$G$7:$G$506,'Breakdown Log'!$C$7:$C$506,H42,'Breakdown Log'!$B$7:$B$506,">="&Setup!$C$7,'Breakdown Log'!$B$7:$B$506,"<="&Setup!$C$8)/60 -> 24.016667
B43: =EDATE(B42,1) -> 46204 | C43: =COUNTIFS('Breakdown Log'!$B$7:$B$506,">="&B43,'Breakdown Log'!$B$7:$B$506,"<"&EDATE(B43,1),'Breakdown Log'!$B$7:$B$506,">="&Setup!$C$7,'Breakdown Log'!$B$7:$B$506,"<="&Setup!$C$8) -> 23 | D43: =SUMIFS('Breakdown Log'!$G$7:$G$506,'Breakdown Log'!$B$7:$B$506,">="&B43,'Breakdown Log'!$B$7:$B$506,"<"&EDATE(B43,1),'Breakdown Log'!$B$7:$B$506,">="&Setup!$C$7,'Breakdown Log'!$B$7:$B$506,"<="&Setup!$C$8)/60 -> 12.7 | E43: =TEXT(B43,"mmm yy") -> Jul 26 | H43: Nights | I43: =COUNTIFS('Breakdown Log'!$C$7:$C$506,H43,'Breakdown Log'!$B$7:$B$506,">="&Setup!$C$7,'Breakdown Log'!$B$7:$B$506,"<="&Setup!$C$8) -> 29 | J43: =SUMIFS('Breakdown Log'!$G$7:$G$506,'Breakdown Log'!$C$7:$C$506,H43,'Breakdown Log'!$B$7:$B$506,">="&Setup!$C$7,'Breakdown Log'!$B$7:$B$506,"<="&Setup!$C$8)/60 -> 13.8
B44: =EDATE(B43,1) -> 46235 | C44: =COUNTIFS('Breakdown Log'!$B$7:$B$506,">="&B44,'Breakdown Log'!$B$7:$B$506,"<"&EDATE(B44,1),'Breakdown Log'!$B$7:$B$506,">="&Setup!$C$7,'Breakdown Log'!$B$7:$B$506,"<="&Setup!$C$8) -> 16 | D44: =SUMIFS('Breakdown Log'!$G$7:$G$506,'Breakdown Log'!$B$7:$B$506,">="&B44,'Breakdown Log'!$B$7:$B$506,"<"&EDATE(B44,1),'Breakdown Log'!$B$7:$B$506,">="&Setup!$C$7,'Breakdown Log'!$B$7:$B$506,"<="&Setup!$C$8)/60 -> 9.0666667 | E44: =TEXT(B44,"mmm yy") -> Aug 26 | H44: Weekend | I44: =COUNTIFS('Breakdown Log'!$C$7:$C$506,H44,'Breakdown Log'!$B$7:$B$506,">="&Setup!$C$7,'Breakdown Log'!$B$7:$B$506,"<="&Setup!$C$8) -> 0 | J44: =SUMIFS('Breakdown Log'!$G$7:$G$506,'Breakdown Log'!$C$7:$C$506,H44,'Breakdown Log'!$B$7:$B$506,">="&Setup!$C$7,'Breakdown Log'!$B$7:$B$506,"<="&Setup!$C$8)/60 -> 0
B45: =EDATE(B44,1) -> 46266 | C45: =COUNTIFS('Breakdown Log'!$B$7:$B$506,">="&B45,'Breakdown Log'!$B$7:$B$506,"<"&EDATE(B45,1),'Breakdown Log'!$B$7:$B$506,">="&Setup!$C$7,'Breakdown Log'!$B$7:$B$506,"<="&Setup!$C$8) -> 19 | D45: =SUMIFS('Breakdown Log'!$G$7:$G$506,'Breakdown Log'!$B$7:$B$506,">="&B45,'Breakdown Log'!$B$7:$B$506,"<"&EDATE(B45,1),'Breakdown Log'!$B$7:$B$506,">="&Setup!$C$7,'Breakdown Log'!$B$7:$B$506,"<="&Setup!$C$8)/60 -> 8.4333333 | E45: =TEXT(B45,"mmm yy") -> Sep 26
B46: =EDATE(B45,1) -> 46296 | C46: =COUNTIFS('Breakdown Log'!$B$7:$B$506,">="&B46,'Breakdown Log'!$B$7:$B$506,"<"&EDATE(B46,1),'Breakdown Log'!$B$7:$B$506,">="&Setup!$C$7,'Breakdown Log'!$B$7:$B$506,"<="&Setup!$C$8) -> 0 | D46: =SUMIFS('Breakdown Log'!$G$7:$G$506,'Breakdown Log'!$B$7:$B$506,">="&B46,'Breakdown Log'!$B$7:$B$506,"<"&EDATE(B46,1),'Breakdown Log'!$B$7:$B$506,">="&Setup!$C$7,'Breakdown Log'!$B$7:$B$506,"<="&Setup!$C$8)/60 -> 0 | E46: =TEXT(B46,"mmm yy") -> Oct 26
...
